Watching for file changes with StatReloader
C:\Users\SUBRAMANI\AppData\Roaming\Python\Python313\site-packages\PIL\TiffTags.py changed, reloading.
Watching for file changes with StatReloader
Watching for file changes with StatReloader
Watching for file changes with StatReloader
Not Found: /
"GET / HTTP/1.1" 404 2773
Not Found: /favicon.ico
"GET /favicon.ico HTTP/1.1" 404 2824
C:\Users\SUBRAMANI\dine\Ecoshift\backend\ecoswitch_backend\settings.py changed, reloading.
Watching for file changes with StatReloader
C:\Users\SUBRAMANI\dine\Ecoshift\backend\ecoswitch_backend\settings.py changed, reloading.
Watching for file changes with StatReloader
"OPTIONS /api/auth/register/ HTTP/1.1" 200 0
Internal Server Error: /api/auth/register/
Traceback (most recent call last):
  File "C:\Users\SUBRAMANI\AppData\Roaming\Python\Python313\site-packages\django\db\backends\utils.py", line 89, in _execute
    return self.cursor.execute(sql, params)
           ~~~~~~~~~~~~~~~~~~~^^^^^^^^^^^^^
  File "C:\Users\SUBRAMANI\AppData\Roaming\Python\Python313\site-packages\django\db\backends\sqlite3\base.py", line 328, in execute
    return super().execute(query, params)
           ~~~~~~~~~~~~~~~^^^^^^^^^^^^^^^
sqlite3.OperationalError: no such table: auth_user

The above exception was the direct cause of the following exception:

Traceback (most recent call last):
  File "C:\Users\SUBRAMANI\AppData\Roaming\Python\Python313\site-packages\django\core\handlers\exception.py", line 55, in inner
    response = get_response(request)
  File "C:\Users\SUBRAMANI\AppData\Roaming\Python\Python313\site-packages\django\core\handlers\base.py", line 197, in _get_response
    response = wrapped_callback(request, *callback_args, **callback_kwargs)
  File "C:\Users\SUBRAMANI\AppData\Roaming\Python\Python313\site-packages\django\views\decorators\csrf.py", line 56, in wrapper_view
    return view_func(*args, **kwargs)
  File "C:\Users\SUBRAMANI\AppData\Roaming\Python\Python313\site-packages\django\views\generic\base.py", line 104, in view
    return self.dispatch(request, *args, **kwargs)
           ~~~~~~~~~~~~~^^^^^^^^^^^^^^^^^^^^^^^^^^
  File "C:\Users\SUBRAMANI\AppData\Roaming\Python\Python313\site-packages\rest_framework\views.py", line 509, in dispatch
    response = self.handle_exception(exc)
  File "C:\Users\SUBRAMANI\AppData\Roaming\Python\Python313\site-packages\rest_framework\views.py", line 469, in handle_exception
    self.raise_uncaught_exception(exc)
    ~~~~~~~~~~~~~~~~~~~~~~~~~~~~~^^^^^
  File "C:\Users\SUBRAMANI\AppData\Roaming\Python\Python313\site-packages\rest_framework\views.py", line 480, in raise_uncaught_exception
    raise exc
  File "C:\Users\SUBRAMANI\AppData\Roaming\Python\Python313\site-packages\rest_framework\views.py", line 506, in dispatch
    response = handler(request, *args, **kwargs)
  File "C:\Users\SUBRAMANI\AppData\Roaming\Python\Python313\site-packages\rest_framework\decorators.py", line 50, in handler
    return func(*args, **kwargs)
  File "C:\Users\SUBRAMANI\dine\Ecoshift\backend\authentication\views.py", line 55, in register_user
    if serializer.is_valid():
       ~~~~~~~~~~~~~~~~~~~^^
  File "C:\Users\SUBRAMANI\AppData\Roaming\Python\Python313\site-packages\rest_framework\serializers.py", line 227, in is_valid
    self._validated_data = self.run_validation(self.initial_data)
                           ~~~~~~~~~~~~~~~~~~~^^^^^^^^^^^^^^^^^^^
  File "C:\Users\SUBRAMANI\AppData\Roaming\Python\Python313\site-packages\rest_framework\serializers.py", line 426, in run_validation
    value = self.to_internal_value(data)
  File "C:\Users\SUBRAMANI\AppData\Roaming\Python\Python313\site-packages\rest_framework\serializers.py", line 483, in to_internal_value
    validated_value = field.run_validation(primitive_value)
  File "C:\Users\SUBRAMANI\AppData\Roaming\Python\Python313\site-packages\rest_framework\fields.py", line 751, in run_validation
    return super().run_validation(data)
           ~~~~~~~~~~~~~~~~~~~~~~^^^^^^
  File "C:\Users\SUBRAMANI\AppData\Roaming\Python\Python313\site-packages\rest_framework\fields.py", line 548, in run_validation
    self.run_validators(value)
    ~~~~~~~~~~~~~~~~~~~^^^^^^^
  File "C:\Users\SUBRAMANI\AppData\Roaming\Python\Python313\site-packages\rest_framework\fields.py", line 560, in run_validators
    validator(value, self)
    ~~~~~~~~~^^^^^^^^^^^^^
  File "C:\Users\SUBRAMANI\AppData\Roaming\Python\Python313\site-packages\rest_framework\validators.py", line 73, in __call__
    if qs_exists(queryset):
       ~~~~~~~~~^^^^^^^^^^
  File "C:\Users\SUBRAMANI\AppData\Roaming\Python\Python313\site-packages\rest_framework\validators.py", line 21, in qs_exists
    return queryset.exists()
           ~~~~~~~~~~~~~~~^^
  File "C:\Users\SUBRAMANI\AppData\Roaming\Python\Python313\site-packages\django\db\models\query.py", line 1241, in exists
    return self.query.has_results(using=self.db)
           ~~~~~~~~~~~~~~~~~~~~~~^^^^^^^^^^^^^^^
  File "C:\Users\SUBRAMANI\AppData\Roaming\Python\Python313\site-packages\django\db\models\sql\query.py", line 598, in has_results
    return compiler.has_results()
           ~~~~~~~~~~~~~~~~~~~~^^
  File "C:\Users\SUBRAMANI\AppData\Roaming\Python\Python313\site-packages\django\db\models\sql\compiler.py", line 1530, in has_results
    return bool(self.execute_sql(SINGLE))
                ~~~~~~~~~~~~~~~~^^^^^^^^
  File "C:\Users\SUBRAMANI\AppData\Roaming\Python\Python313\site-packages\django\db\models\sql\compiler.py", line 1562, in execute_sql
    cursor.execute(sql, params)
    ~~~~~~~~~~~~~~^^^^^^^^^^^^^
  File "C:\Users\SUBRAMANI\AppData\Roaming\Python\Python313\site-packages\django\db\backends\utils.py", line 102, in execute
    return super().execute(sql, params)
           ~~~~~~~~~~~~~~~^^^^^^^^^^^^^
  File "C:\Users\SUBRAMANI\AppData\Roaming\Python\Python313\site-packages\django\db\backends\utils.py", line 67, in execute
    return self._execute_with_wrappers(
           ~~~~~~~~~~~~~~~~~~~~~~~~~~~^
        sql, params, many=False, executor=self._execute
        ^^^^^^^^^^^^^^^^^^^^^^^^^^^^^^^^^^^^^^^^^^^^^^^
    )
    ^
  File "C:\Users\SUBRAMANI\AppData\Roaming\Python\Python313\site-packages\django\db\backends\utils.py", line 80, in _execute_with_wrappers
    return executor(sql, params, many, context)
  File "C:\Users\SUBRAMANI\AppData\Roaming\Python\Python313\site-packages\django\db\backends\utils.py", line 84, in _execute
    with self.db.wrap_database_errors:
         ^^^^^^^^^^^^^^^^^^^^^^^^^^^^
  File "C:\Users\SUBRAMANI\AppData\Roaming\Python\Python313\site-packages\django\db\utils.py", line 91, in __exit__
    raise dj_exc_value.with_traceback(traceback) from exc_value
  File "C:\Users\SUBRAMANI\AppData\Roaming\Python\Python313\site-packages\django\db\backends\utils.py", line 89, in _execute
    return self.cursor.execute(sql, params)
           ~~~~~~~~~~~~~~~~~~~^^^^^^^^^^^^^
  File "C:\Users\SUBRAMANI\AppData\Roaming\Python\Python313\site-packages\django\db\backends\sqlite3\base.py", line 328, in execute
    return super().execute(query, params)
           ~~~~~~~~~~~~~~~^^^^^^^^^^^^^^^
django.db.utils.OperationalError: no such table: auth_user
"POST /api/auth/register/ HTTP/1.1" 500 201193
Internal Server Error: /api/auth/register/
Traceback (most recent call last):
  File "C:\Users\SUBRAMANI\AppData\Roaming\Python\Python313\site-packages\django\db\backends\utils.py", line 89, in _execute
    return self.cursor.execute(sql, params)
           ~~~~~~~~~~~~~~~~~~~^^^^^^^^^^^^^
  File "C:\Users\SUBRAMANI\AppData\Roaming\Python\Python313\site-packages\django\db\backends\sqlite3\base.py", line 328, in execute
    return super().execute(query, params)
           ~~~~~~~~~~~~~~~^^^^^^^^^^^^^^^
sqlite3.OperationalError: no such table: auth_user

The above exception was the direct cause of the following exception:

Traceback (most recent call last):
  File "C:\Users\SUBRAMANI\AppData\Roaming\Python\Python313\site-packages\django\core\handlers\exception.py", line 55, in inner
    response = get_response(request)
  File "C:\Users\SUBRAMANI\AppData\Roaming\Python\Python313\site-packages\django\core\handlers\base.py", line 197, in _get_response
    response = wrapped_callback(request, *callback_args, **callback_kwargs)
  File "C:\Users\SUBRAMANI\AppData\Roaming\Python\Python313\site-packages\django\views\decorators\csrf.py", line 56, in wrapper_view
    return view_func(*args, **kwargs)
  File "C:\Users\SUBRAMANI\AppData\Roaming\Python\Python313\site-packages\django\views\generic\base.py", line 104, in view
    return self.dispatch(request, *args, **kwargs)
           ~~~~~~~~~~~~~^^^^^^^^^^^^^^^^^^^^^^^^^^
  File "C:\Users\SUBRAMANI\AppData\Roaming\Python\Python313\site-packages\rest_framework\views.py", line 509, in dispatch
    response = self.handle_exception(exc)
  File "C:\Users\SUBRAMANI\AppData\Roaming\Python\Python313\site-packages\rest_framework\views.py", line 469, in handle_exception
    self.raise_uncaught_exception(exc)
    ~~~~~~~~~~~~~~~~~~~~~~~~~~~~~^^^^^
  File "C:\Users\SUBRAMANI\AppData\Roaming\Python\Python313\site-packages\rest_framework\views.py", line 480, in raise_uncaught_exception
    raise exc
  File "C:\Users\SUBRAMANI\AppData\Roaming\Python\Python313\site-packages\rest_framework\views.py", line 506, in dispatch
    response = handler(request, *args, **kwargs)
  File "C:\Users\SUBRAMANI\AppData\Roaming\Python\Python313\site-packages\rest_framework\decorators.py", line 50, in handler
    return func(*args, **kwargs)
  File "C:\Users\SUBRAMANI\dine\Ecoshift\backend\authentication\views.py", line 55, in register_user
    if serializer.is_valid():
       ~~~~~~~~~~~~~~~~~~~^^
  File "C:\Users\SUBRAMANI\AppData\Roaming\Python\Python313\site-packages\rest_framework\serializers.py", line 227, in is_valid
    self._validated_data = self.run_validation(self.initial_data)
                           ~~~~~~~~~~~~~~~~~~~^^^^^^^^^^^^^^^^^^^
  File "C:\Users\SUBRAMANI\AppData\Roaming\Python\Python313\site-packages\rest_framework\serializers.py", line 426, in run_validation
    value = self.to_internal_value(data)
  File "C:\Users\SUBRAMANI\AppData\Roaming\Python\Python313\site-packages\rest_framework\serializers.py", line 483, in to_internal_value
    validated_value = field.run_validation(primitive_value)
  File "C:\Users\SUBRAMANI\AppData\Roaming\Python\Python313\site-packages\rest_framework\fields.py", line 751, in run_validation
    return super().run_validation(data)
           ~~~~~~~~~~~~~~~~~~~~~~^^^^^^
  File "C:\Users\SUBRAMANI\AppData\Roaming\Python\Python313\site-packages\rest_framework\fields.py", line 548, in run_validation
    self.run_validators(value)
    ~~~~~~~~~~~~~~~~~~~^^^^^^^
  File "C:\Users\SUBRAMANI\AppData\Roaming\Python\Python313\site-packages\rest_framework\fields.py", line 560, in run_validators
    validator(value, self)
    ~~~~~~~~~^^^^^^^^^^^^^
  File "C:\Users\SUBRAMANI\AppData\Roaming\Python\Python313\site-packages\rest_framework\validators.py", line 73, in __call__
    if qs_exists(queryset):
       ~~~~~~~~~^^^^^^^^^^
  File "C:\Users\SUBRAMANI\AppData\Roaming\Python\Python313\site-packages\rest_framework\validators.py", line 21, in qs_exists
    return queryset.exists()
           ~~~~~~~~~~~~~~~^^
  File "C:\Users\SUBRAMANI\AppData\Roaming\Python\Python313\site-packages\django\db\models\query.py", line 1241, in exists
    return self.query.has_results(using=self.db)
           ~~~~~~~~~~~~~~~~~~~~~~^^^^^^^^^^^^^^^
  File "C:\Users\SUBRAMANI\AppData\Roaming\Python\Python313\site-packages\django\db\models\sql\query.py", line 598, in has_results
    return compiler.has_results()
           ~~~~~~~~~~~~~~~~~~~~^^
  File "C:\Users\SUBRAMANI\AppData\Roaming\Python\Python313\site-packages\django\db\models\sql\compiler.py", line 1530, in has_results
    return bool(self.execute_sql(SINGLE))
                ~~~~~~~~~~~~~~~~^^^^^^^^
  File "C:\Users\SUBRAMANI\AppData\Roaming\Python\Python313\site-packages\django\db\models\sql\compiler.py", line 1562, in execute_sql
    cursor.execute(sql, params)
    ~~~~~~~~~~~~~~^^^^^^^^^^^^^
  File "C:\Users\SUBRAMANI\AppData\Roaming\Python\Python313\site-packages\django\db\backends\utils.py", line 102, in execute
    return super().execute(sql, params)
           ~~~~~~~~~~~~~~~^^^^^^^^^^^^^
  File "C:\Users\SUBRAMANI\AppData\Roaming\Python\Python313\site-packages\django\db\backends\utils.py", line 67, in execute
    return self._execute_with_wrappers(
           ~~~~~~~~~~~~~~~~~~~~~~~~~~~^
        sql, params, many=False, executor=self._execute
        ^^^^^^^^^^^^^^^^^^^^^^^^^^^^^^^^^^^^^^^^^^^^^^^
    )
    ^
  File "C:\Users\SUBRAMANI\AppData\Roaming\Python\Python313\site-packages\django\db\backends\utils.py", line 80, in _execute_with_wrappers
    return executor(sql, params, many, context)
  File "C:\Users\SUBRAMANI\AppData\Roaming\Python\Python313\site-packages\django\db\backends\utils.py", line 84, in _execute
    with self.db.wrap_database_errors:
         ^^^^^^^^^^^^^^^^^^^^^^^^^^^^
  File "C:\Users\SUBRAMANI\AppData\Roaming\Python\Python313\site-packages\django\db\utils.py", line 91, in __exit__
    raise dj_exc_value.with_traceback(traceback) from exc_value
  File "C:\Users\SUBRAMANI\AppData\Roaming\Python\Python313\site-packages\django\db\backends\utils.py", line 89, in _execute
    return self.cursor.execute(sql, params)
           ~~~~~~~~~~~~~~~~~~~^^^^^^^^^^^^^
  File "C:\Users\SUBRAMANI\AppData\Roaming\Python\Python313\site-packages\django\db\backends\sqlite3\base.py", line 328, in execute
    return super().execute(query, params)
           ~~~~~~~~~~~~~~~^^^^^^^^^^^^^^^
django.db.utils.OperationalError: no such table: auth_user
"POST /api/auth/register/ HTTP/1.1" 500 201085
"OPTIONS /api/auth/login/ HTTP/1.1" 200 0
Internal Server Error: /api/auth/login/
Traceback (most recent call last):
  File "C:\Users\SUBRAMANI\AppData\Roaming\Python\Python313\site-packages\django\db\backends\utils.py", line 89, in _execute
    return self.cursor.execute(sql, params)
           ~~~~~~~~~~~~~~~~~~~^^^^^^^^^^^^^
  File "C:\Users\SUBRAMANI\AppData\Roaming\Python\Python313\site-packages\django\db\backends\sqlite3\base.py", line 328, in execute
    return super().execute(query, params)
           ~~~~~~~~~~~~~~~^^^^^^^^^^^^^^^
sqlite3.OperationalError: no such table: auth_user

The above exception was the direct cause of the following exception:

Traceback (most recent call last):
  File "C:\Users\SUBRAMANI\AppData\Roaming\Python\Python313\site-packages\django\core\handlers\exception.py", line 55, in inner
    response = get_response(request)
  File "C:\Users\SUBRAMANI\AppData\Roaming\Python\Python313\site-packages\django\core\handlers\base.py", line 197, in _get_response
    response = wrapped_callback(request, *callback_args, **callback_kwargs)
  File "C:\Users\SUBRAMANI\AppData\Roaming\Python\Python313\site-packages\django\views\decorators\csrf.py", line 56, in wrapper_view
    return view_func(*args, **kwargs)
  File "C:\Users\SUBRAMANI\AppData\Roaming\Python\Python313\site-packages\django\views\generic\base.py", line 104, in view
    return self.dispatch(request, *args, **kwargs)
           ~~~~~~~~~~~~~^^^^^^^^^^^^^^^^^^^^^^^^^^
  File "C:\Users\SUBRAMANI\AppData\Roaming\Python\Python313\site-packages\rest_framework\views.py", line 509, in dispatch
    response = self.handle_exception(exc)
  File "C:\Users\SUBRAMANI\AppData\Roaming\Python\Python313\site-packages\rest_framework\views.py", line 469, in handle_exception
    self.raise_uncaught_exception(exc)
    ~~~~~~~~~~~~~~~~~~~~~~~~~~~~~^^^^^
  File "C:\Users\SUBRAMANI\AppData\Roaming\Python\Python313\site-packages\rest_framework\views.py", line 480, in raise_uncaught_exception
    raise exc
  File "C:\Users\SUBRAMANI\AppData\Roaming\Python\Python313\site-packages\rest_framework\views.py", line 506, in dispatch
    response = handler(request, *args, **kwargs)
  File "C:\Users\SUBRAMANI\dine\Ecoshift\backend\authentication\views.py", line 29, in post
    if serializer.is_valid():
       ~~~~~~~~~~~~~~~~~~~^^
  File "C:\Users\SUBRAMANI\AppData\Roaming\Python\Python313\site-packages\rest_framework\serializers.py", line 227, in is_valid
    self._validated_data = self.run_validation(self.initial_data)
                           ~~~~~~~~~~~~~~~~~~~^^^^^^^^^^^^^^^^^^^
  File "C:\Users\SUBRAMANI\AppData\Roaming\Python\Python313\site-packages\rest_framework\serializers.py", line 429, in run_validation
    value = self.validate(value)
  File "C:\Users\SUBRAMANI\dine\Ecoshift\backend\authentication\serializers.py", line 43, in validate
    user = authenticate(username=email, password=password)
  File "C:\Users\SUBRAMANI\AppData\Roaming\Python\Python313\site-packages\django\views\decorators\debug.py", line 42, in sensitive_variables_wrapper
    return func(*func_args, **func_kwargs)
  File "C:\Users\SUBRAMANI\AppData\Roaming\Python\Python313\site-packages\django\contrib\auth\__init__.py", line 77, in authenticate
    user = backend.authenticate(request, **credentials)
  File "C:\Users\SUBRAMANI\AppData\Roaming\Python\Python313\site-packages\django\contrib\auth\backends.py", line 46, in authenticate
    user = UserModel._default_manager.get_by_natural_key(username)
  File "C:\Users\SUBRAMANI\AppData\Roaming\Python\Python313\site-packages\django\contrib\auth\base_user.py", line 54, in get_by_natural_key
    return self.get(**{self.model.USERNAME_FIELD: username})
           ~~~~~~~~^^^^^^^^^^^^^^^^^^^^^^^^^^^^^^^^^^^^^^^^^
  File "C:\Users\SUBRAMANI\AppData\Roaming\Python\Python313\site-packages\django\db\models\manager.py", line 87, in manager_method
    return getattr(self.get_queryset(), name)(*args, **kwargs)
           ~~~~~~~~~~~~~~~~~~~~~~~~~~~~~~~~~~^^^^^^^^^^^^^^^^^
  File "C:\Users\SUBRAMANI\AppData\Roaming\Python\Python313\site-packages\django\db\models\query.py", line 633, in get
    num = len(clone)
  File "C:\Users\SUBRAMANI\AppData\Roaming\Python\Python313\site-packages\django\db\models\query.py", line 380, in __len__
    self._fetch_all()
    ~~~~~~~~~~~~~~~^^
  File "C:\Users\SUBRAMANI\AppData\Roaming\Python\Python313\site-packages\django\db\models\query.py", line 1881, in _fetch_all
    self._result_cache = list(self._iterable_class(self))
                         ~~~~^^^^^^^^^^^^^^^^^^^^^^^^^^^^
  File "C:\Users\SUBRAMANI\AppData\Roaming\Python\Python313\site-packages\django\db\models\query.py", line 91, in __iter__
    results = compiler.execute_sql(
        chunked_fetch=self.chunked_fetch, chunk_size=self.chunk_size
    )
  File "C:\Users\SUBRAMANI\AppData\Roaming\Python\Python313\site-packages\django\db\models\sql\compiler.py", line 1562, in execute_sql
    cursor.execute(sql, params)
    ~~~~~~~~~~~~~~^^^^^^^^^^^^^
  File "C:\Users\SUBRAMANI\AppData\Roaming\Python\Python313\site-packages\django\db\backends\utils.py", line 102, in execute
    return super().execute(sql, params)
           ~~~~~~~~~~~~~~~^^^^^^^^^^^^^
  File "C:\Users\SUBRAMANI\AppData\Roaming\Python\Python313\site-packages\django\db\backends\utils.py", line 67, in execute
    return self._execute_with_wrappers(
           ~~~~~~~~~~~~~~~~~~~~~~~~~~~^
        sql, params, many=False, executor=self._execute
        ^^^^^^^^^^^^^^^^^^^^^^^^^^^^^^^^^^^^^^^^^^^^^^^
    )
    ^
  File "C:\Users\SUBRAMANI\AppData\Roaming\Python\Python313\site-packages\django\db\backends\utils.py", line 80, in _execute_with_wrappers
    return executor(sql, params, many, context)
  File "C:\Users\SUBRAMANI\AppData\Roaming\Python\Python313\site-packages\django\db\backends\utils.py", line 84, in _execute
    with self.db.wrap_database_errors:
         ^^^^^^^^^^^^^^^^^^^^^^^^^^^^
  File "C:\Users\SUBRAMANI\AppData\Roaming\Python\Python313\site-packages\django\db\utils.py", line 91, in __exit__
    raise dj_exc_value.with_traceback(traceback) from exc_value
  File "C:\Users\SUBRAMANI\AppData\Roaming\Python\Python313\site-packages\django\db\backends\utils.py", line 89, in _execute
    return self.cursor.execute(sql, params)
           ~~~~~~~~~~~~~~~~~~~^^^^^^^^^^^^^
  File "C:\Users\SUBRAMANI\AppData\Roaming\Python\Python313\site-packages\django\db\backends\sqlite3\base.py", line 328, in execute
    return super().execute(query, params)
           ~~~~~~~~~~~~~~~^^^^^^^^^^^^^^^
django.db.utils.OperationalError: no such table: auth_user
"POST /api/auth/login/ HTTP/1.1" 500 203349
Not Found: /
"GET / HTTP/1.1" 404 2773
C:\Users\SUBRAMANI\dine\Ecoshift\backend\merchants\apps.py changed, reloading.
Watching for file changes with StatReloader
C:\Users\SUBRAMANI\dine\Ecoshift\backend\ecoswitch_backend\urls.py changed, reloading.
Watching for file changes with StatReloader
C:\Users\SUBRAMANI\dine\Ecoshift\backend\customers\models.py changed, reloading.
Watching for file changes with StatReloader
C:\Users\SUBRAMANI\dine\Ecoshift\backend\ecoswitch_backend\urls.py changed, reloading.
Watching for file changes with StatReloader
C:\Users\SUBRAMANI\dine\Ecoshift\backend\authentication\serializers.py changed, reloading.
Watching for file changes with StatReloader
Watching for file changes with StatReloader
Watching for file changes with StatReloader
Not Found: /
"GET / HTTP/1.1" 404 2773
Not Found: /favicon.ico
"GET /favicon.ico HTTP/1.1" 404 2824
"GET /admin HTTP/1.1" 301 0
"GET /admin/ HTTP/1.1" 302 0
"GET /admin/login/?next=/admin/ HTTP/1.1" 200 4178
"GET /static/admin/css/base.css HTTP/1.1" 200 21207
"GET /static/admin/css/login.css HTTP/1.1" 200 958
"GET /static/admin/css/responsive.css HTTP/1.1" 200 18533
"GET /static/admin/css/nav_sidebar.css HTTP/1.1" 200 2694
"GET /static/admin/js/nav_sidebar.js HTTP/1.1" 200 3063
"GET /static/admin/css/dark_mode.css HTTP/1.1" 200 2929
"GET /static/admin/js/theme.js HTTP/1.1" 200 1943
Internal Server Error: /admin/login/
Traceback (most recent call last):
  File "C:\Users\SUBRAMANI\AppData\Roaming\Python\Python313\site-packages\django\db\backends\utils.py", line 89, in _execute
    return self.cursor.execute(sql, params)
           ~~~~~~~~~~~~~~~~~~~^^^^^^^^^^^^^
  File "C:\Users\SUBRAMANI\AppData\Roaming\Python\Python313\site-packages\django\db\backends\sqlite3\base.py", line 328, in execute
    return super().execute(query, params)
           ~~~~~~~~~~~~~~~^^^^^^^^^^^^^^^
sqlite3.OperationalError: no such table: auth_user

The above exception was the direct cause of the following exception:

Traceback (most recent call last):
  File "C:\Users\SUBRAMANI\AppData\Roaming\Python\Python313\site-packages\django\core\handlers\exception.py", line 55, in inner
    response = get_response(request)
  File "C:\Users\SUBRAMANI\AppData\Roaming\Python\Python313\site-packages\django\core\handlers\base.py", line 197, in _get_response
    response = wrapped_callback(request, *callback_args, **callback_kwargs)
  File "C:\Users\SUBRAMANI\AppData\Roaming\Python\Python313\site-packages\django\utils\decorators.py", line 46, in _wrapper
    return bound_method(*args, **kwargs)
  File "C:\Users\SUBRAMANI\AppData\Roaming\Python\Python313\site-packages\django\views\decorators\cache.py", line 62, in _wrapper_view_func
    response = view_func(request, *args, **kwargs)
  File "C:\Users\SUBRAMANI\AppData\Roaming\Python\Python313\site-packages\django\contrib\admin\sites.py", line 441, in login
    return LoginView.as_view(**defaults)(request)
           ~~~~~~~~~~~~~~~~~~~~~~~~~~~~~^^^^^^^^^
  File "C:\Users\SUBRAMANI\AppData\Roaming\Python\Python313\site-packages\django\views\generic\base.py", line 104, in view
    return self.dispatch(request, *args, **kwargs)
           ~~~~~~~~~~~~~^^^^^^^^^^^^^^^^^^^^^^^^^^
  File "C:\Users\SUBRAMANI\AppData\Roaming\Python\Python313\site-packages\django\utils\decorators.py", line 46, in _wrapper
    return bound_method(*args, **kwargs)
  File "C:\Users\SUBRAMANI\AppData\Roaming\Python\Python313\site-packages\django\views\decorators\debug.py", line 92, in sensitive_post_parameters_wrapper
    return view(request, *args, **kwargs)
  File "C:\Users\SUBRAMANI\AppData\Roaming\Python\Python313\site-packages\django\utils\decorators.py", line 46, in _wrapper
    return bound_method(*args, **kwargs)
  File "C:\Users\SUBRAMANI\AppData\Roaming\Python\Python313\site-packages\django\utils\decorators.py", line 134, in _wrapper_view
    response = view_func(request, *args, **kwargs)
  File "C:\Users\SUBRAMANI\AppData\Roaming\Python\Python313\site-packages\django\utils\decorators.py", line 46, in _wrapper
    return bound_method(*args, **kwargs)
  File "C:\Users\SUBRAMANI\AppData\Roaming\Python\Python313\site-packages\django\views\decorators\cache.py", line 62, in _wrapper_view_func
    response = view_func(request, *args, **kwargs)
  File "C:\Users\SUBRAMANI\AppData\Roaming\Python\Python313\site-packages\django\contrib\auth\views.py", line 90, in dispatch
    return super().dispatch(request, *args, **kwargs)
           ~~~~~~~~~~~~~~~~^^^^^^^^^^^^^^^^^^^^^^^^^^
  File "C:\Users\SUBRAMANI\AppData\Roaming\Python\Python313\site-packages\django\views\generic\base.py", line 143, in dispatch
    return handler(request, *args, **kwargs)
  File "C:\Users\SUBRAMANI\AppData\Roaming\Python\Python313\site-packages\django\views\generic\edit.py", line 152, in post
    if form.is_valid():
       ~~~~~~~~~~~~~^^
  File "C:\Users\SUBRAMANI\AppData\Roaming\Python\Python313\site-packages\django\forms\forms.py", line 201, in is_valid
    return self.is_bound and not self.errors
                                 ^^^^^^^^^^^
  File "C:\Users\SUBRAMANI\AppData\Roaming\Python\Python313\site-packages\django\forms\forms.py", line 196, in errors
    self.full_clean()
    ~~~~~~~~~~~~~~~^^
  File "C:\Users\SUBRAMANI\AppData\Roaming\Python\Python313\site-packages\django\forms\forms.py", line 434, in full_clean
    self._clean_form()
    ~~~~~~~~~~~~~~~~^^
  File "C:\Users\SUBRAMANI\AppData\Roaming\Python\Python313\site-packages\django\forms\forms.py", line 455, in _clean_form
    cleaned_data = self.clean()
  File "C:\Users\SUBRAMANI\AppData\Roaming\Python\Python313\site-packages\django\contrib\auth\forms.py", line 250, in clean
    self.user_cache = authenticate(
                      ~~~~~~~~~~~~^
        self.request, username=username, password=password
        ^^^^^^^^^^^^^^^^^^^^^^^^^^^^^^^^^^^^^^^^^^^^^^^^^^
    )
    ^
  File "C:\Users\SUBRAMANI\AppData\Roaming\Python\Python313\site-packages\django\views\decorators\debug.py", line 42, in sensitive_variables_wrapper
    return func(*func_args, **func_kwargs)
  File "C:\Users\SUBRAMANI\AppData\Roaming\Python\Python313\site-packages\django\contrib\auth\__init__.py", line 77, in authenticate
    user = backend.authenticate(request, **credentials)
  File "C:\Users\SUBRAMANI\AppData\Roaming\Python\Python313\site-packages\django\contrib\auth\backends.py", line 46, in authenticate
    user = UserModel._default_manager.get_by_natural_key(username)
  File "C:\Users\SUBRAMANI\AppData\Roaming\Python\Python313\site-packages\django\contrib\auth\base_user.py", line 54, in get_by_natural_key
    return self.get(**{self.model.USERNAME_FIELD: username})
           ~~~~~~~~^^^^^^^^^^^^^^^^^^^^^^^^^^^^^^^^^^^^^^^^^
  File "C:\Users\SUBRAMANI\AppData\Roaming\Python\Python313\site-packages\django\db\models\manager.py", line 87, in manager_method
    return getattr(self.get_queryset(), name)(*args, **kwargs)
           ~~~~~~~~~~~~~~~~~~~~~~~~~~~~~~~~~~^^^^^^^^^^^^^^^^^
  File "C:\Users\SUBRAMANI\AppData\Roaming\Python\Python313\site-packages\django\db\models\query.py", line 633, in get
    num = len(clone)
  File "C:\Users\SUBRAMANI\AppData\Roaming\Python\Python313\site-packages\django\db\models\query.py", line 380, in __len__
    self._fetch_all()
    ~~~~~~~~~~~~~~~^^
  File "C:\Users\SUBRAMANI\AppData\Roaming\Python\Python313\site-packages\django\db\models\query.py", line 1881, in _fetch_all
    self._result_cache = list(self._iterable_class(self))
                         ~~~~^^^^^^^^^^^^^^^^^^^^^^^^^^^^
  File "C:\Users\SUBRAMANI\AppData\Roaming\Python\Python313\site-packages\django\db\models\query.py", line 91, in __iter__
    results = compiler.execute_sql(
        chunked_fetch=self.chunked_fetch, chunk_size=self.chunk_size
    )
  File "C:\Users\SUBRAMANI\AppData\Roaming\Python\Python313\site-packages\django\db\models\sql\compiler.py", line 1562, in execute_sql
    cursor.execute(sql, params)
    ~~~~~~~~~~~~~~^^^^^^^^^^^^^
  File "C:\Users\SUBRAMANI\AppData\Roaming\Python\Python313\site-packages\django\db\backends\utils.py", line 102, in execute
    return super().execute(sql, params)
           ~~~~~~~~~~~~~~~^^^^^^^^^^^^^
  File "C:\Users\SUBRAMANI\AppData\Roaming\Python\Python313\site-packages\django\db\backends\utils.py", line 67, in execute
    return self._execute_with_wrappers(
           ~~~~~~~~~~~~~~~~~~~~~~~~~~~^
        sql, params, many=False, executor=self._execute
        ^^^^^^^^^^^^^^^^^^^^^^^^^^^^^^^^^^^^^^^^^^^^^^^
    )
    ^
  File "C:\Users\SUBRAMANI\AppData\Roaming\Python\Python313\site-packages\django\db\backends\utils.py", line 80, in _execute_with_wrappers
    return executor(sql, params, many, context)
  File "C:\Users\SUBRAMANI\AppData\Roaming\Python\Python313\site-packages\django\db\backends\utils.py", line 84, in _execute
    with self.db.wrap_database_errors:
         ^^^^^^^^^^^^^^^^^^^^^^^^^^^^
  File "C:\Users\SUBRAMANI\AppData\Roaming\Python\Python313\site-packages\django\db\utils.py", line 91, in __exit__
    raise dj_exc_value.with_traceback(traceback) from exc_value
  File "C:\Users\SUBRAMANI\AppData\Roaming\Python\Python313\site-packages\django\db\backends\utils.py", line 89, in _execute
    return self.cursor.execute(sql, params)
           ~~~~~~~~~~~~~~~~~~~^^^^^^^^^^^^^
  File "C:\Users\SUBRAMANI\AppData\Roaming\Python\Python313\site-packages\django\db\backends\sqlite3\base.py", line 328, in execute
    return super().execute(query, params)
           ~~~~~~~~~~~~~~~^^^^^^^^^^^^^^^
django.db.utils.OperationalError: no such table: auth_user
"POST /admin/login/?next=/admin/ HTTP/1.1" 500 247245
"GET /admin/login/?next=/admin/ HTTP/1.1" 200 4178
Internal Server Error: /admin/login/
Traceback (most recent call last):
  File "C:\Users\SUBRAMANI\AppData\Roaming\Python\Python313\site-packages\django\db\backends\utils.py", line 89, in _execute
    return self.cursor.execute(sql, params)
           ~~~~~~~~~~~~~~~~~~~^^^^^^^^^^^^^
  File "C:\Users\SUBRAMANI\AppData\Roaming\Python\Python313\site-packages\django\db\backends\sqlite3\base.py", line 328, in execute
    return super().execute(query, params)
           ~~~~~~~~~~~~~~~^^^^^^^^^^^^^^^
sqlite3.OperationalError: no such table: auth_user

The above exception was the direct cause of the following exception:

Traceback (most recent call last):
  File "C:\Users\SUBRAMANI\AppData\Roaming\Python\Python313\site-packages\django\core\handlers\exception.py", line 55, in inner
    response = get_response(request)
  File "C:\Users\SUBRAMANI\AppData\Roaming\Python\Python313\site-packages\django\core\handlers\base.py", line 197, in _get_response
    response = wrapped_callback(request, *callback_args, **callback_kwargs)
  File "C:\Users\SUBRAMANI\AppData\Roaming\Python\Python313\site-packages\django\utils\decorators.py", line 46, in _wrapper
    return bound_method(*args, **kwargs)
  File "C:\Users\SUBRAMANI\AppData\Roaming\Python\Python313\site-packages\django\views\decorators\cache.py", line 62, in _wrapper_view_func
    response = view_func(request, *args, **kwargs)
  File "C:\Users\SUBRAMANI\AppData\Roaming\Python\Python313\site-packages\django\contrib\admin\sites.py", line 441, in login
    return LoginView.as_view(**defaults)(request)
           ~~~~~~~~~~~~~~~~~~~~~~~~~~~~~^^^^^^^^^
  File "C:\Users\SUBRAMANI\AppData\Roaming\Python\Python313\site-packages\django\views\generic\base.py", line 104, in view
    return self.dispatch(request, *args, **kwargs)
           ~~~~~~~~~~~~~^^^^^^^^^^^^^^^^^^^^^^^^^^
  File "C:\Users\SUBRAMANI\AppData\Roaming\Python\Python313\site-packages\django\utils\decorators.py", line 46, in _wrapper
    return bound_method(*args, **kwargs)
  File "C:\Users\SUBRAMANI\AppData\Roaming\Python\Python313\site-packages\django\views\decorators\debug.py", line 92, in sensitive_post_parameters_wrapper
    return view(request, *args, **kwargs)
  File "C:\Users\SUBRAMANI\AppData\Roaming\Python\Python313\site-packages\django\utils\decorators.py", line 46, in _wrapper
    return bound_method(*args, **kwargs)
  File "C:\Users\SUBRAMANI\AppData\Roaming\Python\Python313\site-packages\django\utils\decorators.py", line 134, in _wrapper_view
    response = view_func(request, *args, **kwargs)
  File "C:\Users\SUBRAMANI\AppData\Roaming\Python\Python313\site-packages\django\utils\decorators.py", line 46, in _wrapper
    return bound_method(*args, **kwargs)
  File "C:\Users\SUBRAMANI\AppData\Roaming\Python\Python313\site-packages\django\views\decorators\cache.py", line 62, in _wrapper_view_func
    response = view_func(request, *args, **kwargs)
  File "C:\Users\SUBRAMANI\AppData\Roaming\Python\Python313\site-packages\django\contrib\auth\views.py", line 90, in dispatch
    return super().dispatch(request, *args, **kwargs)
           ~~~~~~~~~~~~~~~~^^^^^^^^^^^^^^^^^^^^^^^^^^
  File "C:\Users\SUBRAMANI\AppData\Roaming\Python\Python313\site-packages\django\views\generic\base.py", line 143, in dispatch
    return handler(request, *args, **kwargs)
  File "C:\Users\SUBRAMANI\AppData\Roaming\Python\Python313\site-packages\django\views\generic\edit.py", line 152, in post
    if form.is_valid():
       ~~~~~~~~~~~~~^^
  File "C:\Users\SUBRAMANI\AppData\Roaming\Python\Python313\site-packages\django\forms\forms.py", line 201, in is_valid
    return self.is_bound and not self.errors
                                 ^^^^^^^^^^^
  File "C:\Users\SUBRAMANI\AppData\Roaming\Python\Python313\site-packages\django\forms\forms.py", line 196, in errors
    self.full_clean()
    ~~~~~~~~~~~~~~~^^
  File "C:\Users\SUBRAMANI\AppData\Roaming\Python\Python313\site-packages\django\forms\forms.py", line 434, in full_clean
    self._clean_form()
    ~~~~~~~~~~~~~~~~^^
  File "C:\Users\SUBRAMANI\AppData\Roaming\Python\Python313\site-packages\django\forms\forms.py", line 455, in _clean_form
    cleaned_data = self.clean()
  File "C:\Users\SUBRAMANI\AppData\Roaming\Python\Python313\site-packages\django\contrib\auth\forms.py", line 250, in clean
    self.user_cache = authenticate(
                      ~~~~~~~~~~~~^
        self.request, username=username, password=password
        ^^^^^^^^^^^^^^^^^^^^^^^^^^^^^^^^^^^^^^^^^^^^^^^^^^
    )
    ^
  File "C:\Users\SUBRAMANI\AppData\Roaming\Python\Python313\site-packages\django\views\decorators\debug.py", line 42, in sensitive_variables_wrapper
    return func(*func_args, **func_kwargs)
  File "C:\Users\SUBRAMANI\AppData\Roaming\Python\Python313\site-packages\django\contrib\auth\__init__.py", line 77, in authenticate
    user = backend.authenticate(request, **credentials)
  File "C:\Users\SUBRAMANI\AppData\Roaming\Python\Python313\site-packages\django\contrib\auth\backends.py", line 46, in authenticate
    user = UserModel._default_manager.get_by_natural_key(username)
  File "C:\Users\SUBRAMANI\AppData\Roaming\Python\Python313\site-packages\django\contrib\auth\base_user.py", line 54, in get_by_natural_key
    return self.get(**{self.model.USERNAME_FIELD: username})
           ~~~~~~~~^^^^^^^^^^^^^^^^^^^^^^^^^^^^^^^^^^^^^^^^^
  File "C:\Users\SUBRAMANI\AppData\Roaming\Python\Python313\site-packages\django\db\models\manager.py", line 87, in manager_method
    return getattr(self.get_queryset(), name)(*args, **kwargs)
           ~~~~~~~~~~~~~~~~~~~~~~~~~~~~~~~~~~^^^^^^^^^^^^^^^^^
  File "C:\Users\SUBRAMANI\AppData\Roaming\Python\Python313\site-packages\django\db\models\query.py", line 633, in get
    num = len(clone)
  File "C:\Users\SUBRAMANI\AppData\Roaming\Python\Python313\site-packages\django\db\models\query.py", line 380, in __len__
    self._fetch_all()
    ~~~~~~~~~~~~~~~^^
  File "C:\Users\SUBRAMANI\AppData\Roaming\Python\Python313\site-packages\django\db\models\query.py", line 1881, in _fetch_all
    self._result_cache = list(self._iterable_class(self))
                         ~~~~^^^^^^^^^^^^^^^^^^^^^^^^^^^^
  File "C:\Users\SUBRAMANI\AppData\Roaming\Python\Python313\site-packages\django\db\models\query.py", line 91, in __iter__
    results = compiler.execute_sql(
        chunked_fetch=self.chunked_fetch, chunk_size=self.chunk_size
    )
  File "C:\Users\SUBRAMANI\AppData\Roaming\Python\Python313\site-packages\django\db\models\sql\compiler.py", line 1562, in execute_sql
    cursor.execute(sql, params)
    ~~~~~~~~~~~~~~^^^^^^^^^^^^^
  File "C:\Users\SUBRAMANI\AppData\Roaming\Python\Python313\site-packages\django\db\backends\utils.py", line 102, in execute
    return super().execute(sql, params)
           ~~~~~~~~~~~~~~~^^^^^^^^^^^^^
  File "C:\Users\SUBRAMANI\AppData\Roaming\Python\Python313\site-packages\django\db\backends\utils.py", line 67, in execute
    return self._execute_with_wrappers(
           ~~~~~~~~~~~~~~~~~~~~~~~~~~~^
        sql, params, many=False, executor=self._execute
        ^^^^^^^^^^^^^^^^^^^^^^^^^^^^^^^^^^^^^^^^^^^^^^^
    )
    ^
  File "C:\Users\SUBRAMANI\AppData\Roaming\Python\Python313\site-packages\django\db\backends\utils.py", line 80, in _execute_with_wrappers
    return executor(sql, params, many, context)
  File "C:\Users\SUBRAMANI\AppData\Roaming\Python\Python313\site-packages\django\db\backends\utils.py", line 84, in _execute
    with self.db.wrap_database_errors:
         ^^^^^^^^^^^^^^^^^^^^^^^^^^^^
  File "C:\Users\SUBRAMANI\AppData\Roaming\Python\Python313\site-packages\django\db\utils.py", line 91, in __exit__
    raise dj_exc_value.with_traceback(traceback) from exc_value
  File "C:\Users\SUBRAMANI\AppData\Roaming\Python\Python313\site-packages\django\db\backends\utils.py", line 89, in _execute
    return self.cursor.execute(sql, params)
           ~~~~~~~~~~~~~~~~~~~^^^^^^^^^^^^^
  File "C:\Users\SUBRAMANI\AppData\Roaming\Python\Python313\site-packages\django\db\backends\sqlite3\base.py", line 328, in execute
    return super().execute(query, params)
           ~~~~~~~~~~~~~~~^^^^^^^^^^^^^^^
django.db.utils.OperationalError: no such table: auth_user
"POST /admin/login/?next=/admin/ HTTP/1.1" 500 247245
"GET /admin/login/?next=/admin/ HTTP/1.1" 200 4178
Watching for file changes with StatReloader
Not Found: /
"GET / HTTP/1.1" 404 2773
"GET /admin/login/?next=/admin/ HTTP/1.1" 200 4178
